"""Test generac setup process."""
from unittest.mock import patch

import pytest
from custom_components.generac import async_reload_entry
from custom_components.generac import async_setup_entry
from custom_components.generac import async_unload_entry
from custom_components.generac.const import DOMAIN
from homeassistant.core import HomeAssistant
from homeassistant.exceptions import ConfigEntryNotReady
from pytest_homeassistant_custom_component.common import MockConfigEntry

MOCK_CONFIG = {"session_cookie": "test_cookie"}


async def test_setup_unload_and_reload_entry(hass: HomeAssistant, bypass_get_data):
    """Test entry setup and unload."""
    # Create a mock entry so we don't have to go through config flow
    config_entry = MockConfigEntry(domain=DOMAIN, data=MOCK_CONFIG, entry_id="test")
    config_entry.add_to_hass(hass)

    # Set up the entry and assert that the values set during setup are where we expect
    # them to be. Because we have a mock coordinator, none of the values is actually
    # filled in.
    await hass.config_entries.async_setup(config_entry.entry_id)
    assert await async_setup_entry(hass, config_entry)
    assert DOMAIN in hass.data and config_entry.entry_id in hass.data[DOMAIN]

    # Reload the entry and assert that the data from above is still there
    assert await async_reload_entry(hass, config_entry) is None
    assert DOMAIN in hass.data and config_entry.entry_id in hass.data[DOMAIN]

    # Unload the entry and verify that the data has been removed
    assert await async_unload_entry(hass, config_entry)
    assert config_entry.entry_id not in hass.data[DOMAIN]


async def test_setup_entry_exception(hass: HomeAssistant, error_on_get_data):
    """Test config entry not ready."""
    # Create a mock entry so we don't have to go through config flow
    config_entry = MockConfigEntry(domain=DOMAIN, data=MOCK_CONFIG, entry_id="test")
    config_entry.add_to_hass(hass)

    # In this case we are testing the condition where async_setup_entry raises
    # ConfigEntryNotReady using the `error_on_get_data` fixture which simulates
    # an error fetching the data.
    with pytest.raises(ConfigEntryNotReady):
        await async_setup_entry(hass, config_entry)


async def test_setup_entry_existing_domain(hass: HomeAssistant, bypass_get_data):
    """Test entry setup with existing domain data."""
    hass.data[DOMAIN] = {"existing_entry": "data"}
    config_entry = MockConfigEntry(domain=DOMAIN, data=MOCK_CONFIG, entry_id="test")
    config_entry.add_to_hass(hass)

    await hass.config_entries.async_setup(config_entry.entry_id)
    assert await async_setup_entry(hass, config_entry)
    assert DOMAIN in hass.data and config_entry.entry_id in hass.data[DOMAIN]
    assert "existing_entry" in hass.data[DOMAIN]


async def test_unload_entry_failed(hass: HomeAssistant, bypass_get_data):
    """Test entry unload failed."""
    config_entry = MockConfigEntry(domain=DOMAIN, data=MOCK_CONFIG, entry_id="test")
    config_entry.add_to_hass(hass)

    await hass.config_entries.async_setup(config_entry.entry_id)
    assert await async_setup_entry(hass, config_entry)

    with patch(
        "homeassistant.config_entries.ConfigEntries.async_unload_platforms",
        return_value=False,
    ):
        assert not await async_unload_entry(hass, config_entry)
        assert config_entry.entry_id in hass.data[DOMAIN]
